<!-- zumy description-->
<robot name="zumy">

  <link name="world"/>

  <joint name="world_to_zumy" type="fixed">
    <parent link="world"/>
    <child link="base_link"/>
  </joint>

  <link name="base_link">
    <visual>
      <geometry>
        <box size="0.16 0.1 0.05"/>
      </geometry>
      <origin rpy="0 0 0" xyz="0 0 0.085"/>
      <material name="white">
        <color rgba="1 1 1 1"/>
      </material>
    </visual>
  </link>
  
  <link name="lwheel">
    <visual>
      <geometry>
        <cylinder length="0.008" radius="0.046"/>
      </geometry>
      <origin rpy="0 0 0" xyz="0 0 0"/>
      <material name="black">
        <color rgba="0 0 0 1"/>
      </material>
    </visual>
  </link>
  
  <joint name="base_to_lwheel" type="continuous">
    <parent link="base_link"/>
    <child link="lwheel"/>
    <origin xyz="0 0.115 0.046" rpy="1.5708 0 0"/>
    <axis xyz="0 0 1"/>
  </joint>
  
  <link name="rwheel">
    <visual>
      <geometry>
        <cylinder length="0.008" radius="0.046"/>
      </geometry>
      <origin rpy="0 0 0" xyz="0 0 0"/>
      <material name="black">
        <color rgba="0 0 0 1"/>
      </material>
    </visual>
  </link>
  
  <joint name="base_to_rwheel" type="continuous">
    <parent link="base_link"/>
    <child link="rwheel"/>
    <origin xyz="0 -0.115 0.046" rpy="-1.5708 0 0"/>
    <axis xyz="0 0 1"/>
  </joint>
  
  <link name="scanner">
    <visual>
      <geometry>
        <box size="0.015 0.045 0.015"/>
      </geometry>
      <origin rpy="0 0 0" xyz="0.022 0 0.015"/>
      <material name="black">
        <color rgba="0 0 0 1"/>
      </material>
    </visual>
  </link>
  
  <joint name="base_to_scanner" type="fixed">
    <parent link="base_link"/>
    <child link="scanner"/>
    <origin xyz="0.105 0 0.22" rpy="0 0 0"/>
  </joint>

  
</robot>




